[2023-10-30 18:49:34,473][flwr][INFO] - Starting Flower simulation, config: ServerConfig(num_rounds=5, round_timeout=None)
[2023-10-30 18:49:40,739][flwr][INFO] - Flower VCE: Ray initialized with resources: {'object_store_memory': 1355151360.0, 'node:127.0.0.1': 1.0, 'CPU': 4.0, 'memory': 2710302720.0}
[2023-10-30 18:49:40,741][flwr][INFO] - Initializing global parameters
[2023-10-30 18:49:40,741][flwr][INFO] - Requesting initial parameters from one random client
[2023-10-30 18:49:44,350][flwr][INFO] - Received initial parameters from one random client
[2023-10-30 18:49:44,351][flwr][INFO] - Evaluating initial parameters
[2023-10-30 18:49:46,882][flwr][INFO] - initial parameters (loss, other metrics): 182.53371858596802, {'accuracy': 0.1069}
[2023-10-30 18:49:46,882][flwr][INFO] - FL starting
[2023-10-30 18:49:46,883][flwr][DEBUG] - fit_round 1: strategy sampled 10 clients (out of 100)
[2023-10-30 18:49:49,403][flwr][ERROR] - [36mray::launch_and_fit()[39m (pid=4080, ip=127.0.0.1)
  File "/Users/tuliopolido/miniconda3/envs/FederatedLearning/lib/python3.8/site-packages/flwr/simulation/ray_transport/ray_client_proxy.py", line 148, in launch_and_fit
    return maybe_call_fit(
  File "/Users/tuliopolido/miniconda3/envs/FederatedLearning/lib/python3.8/site-packages/flwr/client/client.py", line 184, in maybe_call_fit
    return client.fit(fit_ins)
  File "/Users/tuliopolido/miniconda3/envs/FederatedLearning/lib/python3.8/site-packages/flwr/client/app.py", line 297, in _fit
    results = self.numpy_client.fit(parameters, ins.config)  # type: ignore
  File "/Users/tuliopolido/Repos/ProjetoAnaliseMobilidade/client.py", line 68, in fit
    train(self.model, self.trainloader, optim, epochs, self.device)
  File "/Users/tuliopolido/Repos/ProjetoAnaliseMobilidade/model.py", line 39, in train
    for images, labels in trainloader:
  File "/Users/tuliopolido/miniconda3/envs/FederatedLearning/lib/python3.8/site-packages/torch/utils/data/dataloader.py", line 628, in __next__
    data = self._next_data()
  File "/Users/tuliopolido/miniconda3/envs/FederatedLearning/lib/python3.8/site-packages/torch/utils/data/dataloader.py", line 1316, in _next_data
    idx, data = self._get_data()
  File "/Users/tuliopolido/miniconda3/envs/FederatedLearning/lib/python3.8/site-packages/torch/utils/data/dataloader.py", line 1282, in _get_data
    success, data = self._try_get_data()
  File "/Users/tuliopolido/miniconda3/envs/FederatedLearning/lib/python3.8/site-packages/torch/utils/data/dataloader.py", line 1120, in _try_get_data
    data = self._data_queue.get(timeout=timeout)
  File "/Users/tuliopolido/miniconda3/envs/FederatedLearning/lib/python3.8/multiprocessing/queues.py", line 107, in get
    if not self._poll(timeout):
  File "/Users/tuliopolido/miniconda3/envs/FederatedLearning/lib/python3.8/multiprocessing/connection.py", line 257, in poll
    return self._poll(timeout)
  File "/Users/tuliopolido/miniconda3/envs/FederatedLearning/lib/python3.8/multiprocessing/connection.py", line 424, in _poll
    r = wait([self], timeout)
  File "/Users/tuliopolido/miniconda3/envs/FederatedLearning/lib/python3.8/multiprocessing/connection.py", line 931, in wait
    ready = selector.select(timeout)
  File "/Users/tuliopolido/miniconda3/envs/FederatedLearning/lib/python3.8/selectors.py", line 415, in select
    fd_event_list = self._selector.poll(timeout)
KeyboardInterrupt

During handling of the above exception, another exception occurred:

[36mray::launch_and_fit()[39m (pid=4080, ip=127.0.0.1)
ray.exceptions.TaskCancelledError: Task: TaskID(b99f4f30e1b7a029ffffffffffffffffffffffff01000000) was cancelled
[2023-10-30 18:49:52,663][flwr][ERROR] - [36mray::launch_and_fit()[39m (pid=4078, ip=127.0.0.1)
  File "/Users/tuliopolido/miniconda3/envs/FederatedLearning/lib/python3.8/site-packages/flwr/simulation/ray_transport/ray_client_proxy.py", line 148, in launch_and_fit
    return maybe_call_fit(
  File "/Users/tuliopolido/miniconda3/envs/FederatedLearning/lib/python3.8/site-packages/flwr/client/client.py", line 184, in maybe_call_fit
    return client.fit(fit_ins)
  File "/Users/tuliopolido/miniconda3/envs/FederatedLearning/lib/python3.8/site-packages/flwr/client/app.py", line 297, in _fit
    results = self.numpy_client.fit(parameters, ins.config)  # type: ignore
  File "/Users/tuliopolido/Repos/ProjetoAnaliseMobilidade/client.py", line 68, in fit
    train(self.model, self.trainloader, optim, epochs, self.device)
  File "/Users/tuliopolido/Repos/ProjetoAnaliseMobilidade/model.py", line 39, in train
    for images, labels in trainloader:
  File "/Users/tuliopolido/miniconda3/envs/FederatedLearning/lib/python3.8/site-packages/torch/utils/data/dataloader.py", line 435, in __iter__
    return self._get_iterator()
  File "/Users/tuliopolido/miniconda3/envs/FederatedLearning/lib/python3.8/site-packages/torch/utils/data/dataloader.py", line 381, in _get_iterator
    return _MultiProcessingDataLoaderIter(self)
  File "/Users/tuliopolido/miniconda3/envs/FederatedLearning/lib/python3.8/site-packages/torch/utils/data/dataloader.py", line 1007, in __init__
    self._worker_result_queue = multiprocessing_context.Queue()  # type: ignore[var-annotated]
  File "/Users/tuliopolido/miniconda3/envs/FederatedLearning/lib/python3.8/multiprocessing/context.py", line 103, in Queue
    return Queue(maxsize, ctx=self.get_context())
  File "/Users/tuliopolido/miniconda3/envs/FederatedLearning/lib/python3.8/multiprocessing/queues.py", line 42, in __init__
    self._rlock = ctx.Lock()
  File "/Users/tuliopolido/miniconda3/envs/FederatedLearning/lib/python3.8/multiprocessing/context.py", line 68, in Lock
    return Lock(ctx=self.get_context())
  File "/Users/tuliopolido/miniconda3/envs/FederatedLearning/lib/python3.8/multiprocessing/synchronize.py", line 162, in __init__
    SemLock.__init__(self, SEMAPHORE, 1, 1, ctx=ctx)
  File "/Users/tuliopolido/miniconda3/envs/FederatedLearning/lib/python3.8/multiprocessing/synchronize.py", line 80, in __init__
    register(self._semlock.name, "semaphore")
  File "/Users/tuliopolido/miniconda3/envs/FederatedLearning/lib/python3.8/multiprocessing/resource_tracker.py", line 147, in register
    self._send('REGISTER', name, rtype)
  File "/Users/tuliopolido/miniconda3/envs/FederatedLearning/lib/python3.8/multiprocessing/resource_tracker.py", line 154, in _send
    self.ensure_running()
  File "/Users/tuliopolido/miniconda3/envs/FederatedLearning/lib/python3.8/multiprocessing/resource_tracker.py", line 124, in ensure_running
    signal.pthread_sigmask(signal.SIG_UNBLOCK, _IGNORED_SIGNALS)
  File "/Users/tuliopolido/miniconda3/envs/FederatedLearning/lib/python3.8/signal.py", line 60, in pthread_sigmask
    sigs_set = _signal.pthread_sigmask(how, mask)
KeyboardInterrupt

During handling of the above exception, another exception occurred:

[36mray::launch_and_fit()[39m (pid=4078, ip=127.0.0.1)
ray.exceptions.TaskCancelledError: Task: TaskID(79ebc0b9f017f5b2ffffffffffffffffffffffff01000000) was cancelled
[2023-10-30 18:49:52,718][flwr][ERROR] - [36mray::launch_and_fit()[39m (pid=4079, ip=127.0.0.1)
  File "/Users/tuliopolido/miniconda3/envs/FederatedLearning/lib/python3.8/site-packages/flwr/simulation/ray_transport/ray_client_proxy.py", line 148, in launch_and_fit
    return maybe_call_fit(
  File "/Users/tuliopolido/miniconda3/envs/FederatedLearning/lib/python3.8/site-packages/flwr/client/client.py", line 184, in maybe_call_fit
    return client.fit(fit_ins)
  File "/Users/tuliopolido/miniconda3/envs/FederatedLearning/lib/python3.8/site-packages/flwr/client/app.py", line 297, in _fit
    results = self.numpy_client.fit(parameters, ins.config)  # type: ignore
  File "/Users/tuliopolido/Repos/ProjetoAnaliseMobilidade/client.py", line 68, in fit
    train(self.model, self.trainloader, optim, epochs, self.device)
  File "/Users/tuliopolido/Repos/ProjetoAnaliseMobilidade/model.py", line 39, in train
    for images, labels in trainloader:
  File "/Users/tuliopolido/miniconda3/envs/FederatedLearning/lib/python3.8/site-packages/torch/utils/data/dataloader.py", line 435, in __iter__
    return self._get_iterator()
  File "/Users/tuliopolido/miniconda3/envs/FederatedLearning/lib/python3.8/site-packages/torch/utils/data/dataloader.py", line 381, in _get_iterator
    return _MultiProcessingDataLoaderIter(self)
  File "/Users/tuliopolido/miniconda3/envs/FederatedLearning/lib/python3.8/site-packages/torch/utils/data/dataloader.py", line 1007, in __init__
    self._worker_result_queue = multiprocessing_context.Queue()  # type: ignore[var-annotated]
  File "/Users/tuliopolido/miniconda3/envs/FederatedLearning/lib/python3.8/multiprocessing/context.py", line 103, in Queue
    return Queue(maxsize, ctx=self.get_context())
  File "/Users/tuliopolido/miniconda3/envs/FederatedLearning/lib/python3.8/multiprocessing/queues.py", line 42, in __init__
    self._rlock = ctx.Lock()
  File "/Users/tuliopolido/miniconda3/envs/FederatedLearning/lib/python3.8/multiprocessing/context.py", line 68, in Lock
    return Lock(ctx=self.get_context())
  File "/Users/tuliopolido/miniconda3/envs/FederatedLearning/lib/python3.8/multiprocessing/synchronize.py", line 162, in __init__
    SemLock.__init__(self, SEMAPHORE, 1, 1, ctx=ctx)
  File "/Users/tuliopolido/miniconda3/envs/FederatedLearning/lib/python3.8/multiprocessing/synchronize.py", line 80, in __init__
    register(self._semlock.name, "semaphore")
  File "/Users/tuliopolido/miniconda3/envs/FederatedLearning/lib/python3.8/multiprocessing/resource_tracker.py", line 147, in register
    self._send('REGISTER', name, rtype)
  File "/Users/tuliopolido/miniconda3/envs/FederatedLearning/lib/python3.8/multiprocessing/resource_tracker.py", line 154, in _send
    self.ensure_running()
  File "/Users/tuliopolido/miniconda3/envs/FederatedLearning/lib/python3.8/multiprocessing/resource_tracker.py", line 124, in ensure_running
    signal.pthread_sigmask(signal.SIG_UNBLOCK, _IGNORED_SIGNALS)
  File "/Users/tuliopolido/miniconda3/envs/FederatedLearning/lib/python3.8/signal.py", line 60, in pthread_sigmask
    sigs_set = _signal.pthread_sigmask(how, mask)
KeyboardInterrupt

During handling of the above exception, another exception occurred:

[36mray::launch_and_fit()[39m (pid=4079, ip=127.0.0.1)
ray.exceptions.TaskCancelledError: Task: TaskID(8813c77e894a98b4ffffffffffffffffffffffff01000000) was cancelled
[2023-10-30 18:49:52,979][flwr][ERROR] - [36mray::launch_and_fit()[39m (pid=4077, ip=127.0.0.1)
  File "/Users/tuliopolido/miniconda3/envs/FederatedLearning/lib/python3.8/site-packages/flwr/simulation/ray_transport/ray_client_proxy.py", line 148, in launch_and_fit
    return maybe_call_fit(
  File "/Users/tuliopolido/miniconda3/envs/FederatedLearning/lib/python3.8/site-packages/flwr/client/client.py", line 184, in maybe_call_fit
    return client.fit(fit_ins)
  File "/Users/tuliopolido/miniconda3/envs/FederatedLearning/lib/python3.8/site-packages/flwr/client/app.py", line 297, in _fit
    results = self.numpy_client.fit(parameters, ins.config)  # type: ignore
  File "/Users/tuliopolido/Repos/ProjetoAnaliseMobilidade/client.py", line 68, in fit
    train(self.model, self.trainloader, optim, epochs, self.device)
  File "/Users/tuliopolido/Repos/ProjetoAnaliseMobilidade/model.py", line 39, in train
    for images, labels in trainloader:
  File "/Users/tuliopolido/miniconda3/envs/FederatedLearning/lib/python3.8/site-packages/torch/utils/data/dataloader.py", line 435, in __iter__
    return self._get_iterator()
  File "/Users/tuliopolido/miniconda3/envs/FederatedLearning/lib/python3.8/site-packages/torch/utils/data/dataloader.py", line 381, in _get_iterator
    return _MultiProcessingDataLoaderIter(self)
  File "/Users/tuliopolido/miniconda3/envs/FederatedLearning/lib/python3.8/site-packages/torch/utils/data/dataloader.py", line 1007, in __init__
    self._worker_result_queue = multiprocessing_context.Queue()  # type: ignore[var-annotated]
  File "/Users/tuliopolido/miniconda3/envs/FederatedLearning/lib/python3.8/multiprocessing/context.py", line 103, in Queue
    return Queue(maxsize, ctx=self.get_context())
  File "/Users/tuliopolido/miniconda3/envs/FederatedLearning/lib/python3.8/multiprocessing/queues.py", line 42, in __init__
    self._rlock = ctx.Lock()
  File "/Users/tuliopolido/miniconda3/envs/FederatedLearning/lib/python3.8/multiprocessing/context.py", line 68, in Lock
    return Lock(ctx=self.get_context())
  File "/Users/tuliopolido/miniconda3/envs/FederatedLearning/lib/python3.8/multiprocessing/synchronize.py", line 162, in __init__
    SemLock.__init__(self, SEMAPHORE, 1, 1, ctx=ctx)
  File "/Users/tuliopolido/miniconda3/envs/FederatedLearning/lib/python3.8/multiprocessing/synchronize.py", line 80, in __init__
    register(self._semlock.name, "semaphore")
  File "/Users/tuliopolido/miniconda3/envs/FederatedLearning/lib/python3.8/multiprocessing/resource_tracker.py", line 147, in register
    self._send('REGISTER', name, rtype)
  File "/Users/tuliopolido/miniconda3/envs/FederatedLearning/lib/python3.8/multiprocessing/resource_tracker.py", line 154, in _send
    self.ensure_running()
  File "/Users/tuliopolido/miniconda3/envs/FederatedLearning/lib/python3.8/multiprocessing/resource_tracker.py", line 124, in ensure_running
    signal.pthread_sigmask(signal.SIG_UNBLOCK, _IGNORED_SIGNALS)
  File "/Users/tuliopolido/miniconda3/envs/FederatedLearning/lib/python3.8/signal.py", line 60, in pthread_sigmask
    sigs_set = _signal.pthread_sigmask(how, mask)
KeyboardInterrupt

During handling of the above exception, another exception occurred:

[36mray::launch_and_fit()[39m (pid=4077, ip=127.0.0.1)
ray.exceptions.TaskCancelledError: Task: TaskID(e02329c86c19c501ffffffffffffffffffffffff01000000) was cancelled
[2023-10-30 18:49:55,969][flwr][ERROR] - [36mray::launch_and_fit()[39m (pid=4077, ip=127.0.0.1)
  File "/Users/tuliopolido/miniconda3/envs/FederatedLearning/lib/python3.8/site-packages/flwr/simulation/ray_transport/ray_client_proxy.py", line 148, in launch_and_fit
    return maybe_call_fit(
  File "/Users/tuliopolido/miniconda3/envs/FederatedLearning/lib/python3.8/site-packages/flwr/client/client.py", line 184, in maybe_call_fit
    return client.fit(fit_ins)
  File "/Users/tuliopolido/miniconda3/envs/FederatedLearning/lib/python3.8/site-packages/flwr/client/app.py", line 297, in _fit
    results = self.numpy_client.fit(parameters, ins.config)  # type: ignore
  File "/Users/tuliopolido/Repos/ProjetoAnaliseMobilidade/client.py", line 68, in fit
    train(self.model, self.trainloader, optim, epochs, self.device)
  File "/Users/tuliopolido/Repos/ProjetoAnaliseMobilidade/model.py", line 39, in train
    for images, labels in trainloader:
  File "/Users/tuliopolido/miniconda3/envs/FederatedLearning/lib/python3.8/site-packages/torch/utils/data/dataloader.py", line 628, in __next__
    data = self._next_data()
  File "/Users/tuliopolido/miniconda3/envs/FederatedLearning/lib/python3.8/site-packages/torch/utils/data/dataloader.py", line 1316, in _next_data
    idx, data = self._get_data()
  File "/Users/tuliopolido/miniconda3/envs/FederatedLearning/lib/python3.8/site-packages/torch/utils/data/dataloader.py", line 1282, in _get_data
    success, data = self._try_get_data()
  File "/Users/tuliopolido/miniconda3/envs/FederatedLearning/lib/python3.8/site-packages/torch/utils/data/dataloader.py", line 1120, in _try_get_data
    data = self._data_queue.get(timeout=timeout)
  File "/Users/tuliopolido/miniconda3/envs/FederatedLearning/lib/python3.8/multiprocessing/queues.py", line 107, in get
    if not self._poll(timeout):
  File "/Users/tuliopolido/miniconda3/envs/FederatedLearning/lib/python3.8/multiprocessing/connection.py", line 257, in poll
    return self._poll(timeout)
  File "/Users/tuliopolido/miniconda3/envs/FederatedLearning/lib/python3.8/multiprocessing/connection.py", line 424, in _poll
    r = wait([self], timeout)
  File "/Users/tuliopolido/miniconda3/envs/FederatedLearning/lib/python3.8/multiprocessing/connection.py", line 931, in wait
    ready = selector.select(timeout)
  File "/Users/tuliopolido/miniconda3/envs/FederatedLearning/lib/python3.8/selectors.py", line 415, in select
    fd_event_list = self._selector.poll(timeout)
KeyboardInterrupt

During handling of the above exception, another exception occurred:

[36mray::launch_and_fit()[39m (pid=4077, ip=127.0.0.1)
ray.exceptions.TaskCancelledError: Task: TaskID(b2f2124bfb035771ffffffffffffffffffffffff01000000) was cancelled
[2023-10-30 18:49:56,699][flwr][ERROR] - [36mray::launch_and_fit()[39m (pid=4078, ip=127.0.0.1)
  File "/Users/tuliopolido/miniconda3/envs/FederatedLearning/lib/python3.8/site-packages/flwr/simulation/ray_transport/ray_client_proxy.py", line 148, in launch_and_fit
    return maybe_call_fit(
  File "/Users/tuliopolido/miniconda3/envs/FederatedLearning/lib/python3.8/site-packages/flwr/client/client.py", line 184, in maybe_call_fit
    return client.fit(fit_ins)
  File "/Users/tuliopolido/miniconda3/envs/FederatedLearning/lib/python3.8/site-packages/flwr/client/app.py", line 297, in _fit
    results = self.numpy_client.fit(parameters, ins.config)  # type: ignore
  File "/Users/tuliopolido/Repos/ProjetoAnaliseMobilidade/client.py", line 68, in fit
    train(self.model, self.trainloader, optim, epochs, self.device)
  File "/Users/tuliopolido/Repos/ProjetoAnaliseMobilidade/model.py", line 39, in train
    for images, labels in trainloader:
  File "/Users/tuliopolido/miniconda3/envs/FederatedLearning/lib/python3.8/site-packages/torch/utils/data/dataloader.py", line 628, in __next__
    data = self._next_data()
  File "/Users/tuliopolido/miniconda3/envs/FederatedLearning/lib/python3.8/site-packages/torch/utils/data/dataloader.py", line 1316, in _next_data
    idx, data = self._get_data()
  File "/Users/tuliopolido/miniconda3/envs/FederatedLearning/lib/python3.8/site-packages/torch/utils/data/dataloader.py", line 1282, in _get_data
    success, data = self._try_get_data()
  File "/Users/tuliopolido/miniconda3/envs/FederatedLearning/lib/python3.8/site-packages/torch/utils/data/dataloader.py", line 1120, in _try_get_data
    data = self._data_queue.get(timeout=timeout)
  File "/Users/tuliopolido/miniconda3/envs/FederatedLearning/lib/python3.8/multiprocessing/queues.py", line 107, in get
    if not self._poll(timeout):
  File "/Users/tuliopolido/miniconda3/envs/FederatedLearning/lib/python3.8/multiprocessing/connection.py", line 257, in poll
    return self._poll(timeout)
  File "/Users/tuliopolido/miniconda3/envs/FederatedLearning/lib/python3.8/multiprocessing/connection.py", line 424, in _poll
    r = wait([self], timeout)
  File "/Users/tuliopolido/miniconda3/envs/FederatedLearning/lib/python3.8/multiprocessing/connection.py", line 931, in wait
    ready = selector.select(timeout)
  File "/Users/tuliopolido/miniconda3/envs/FederatedLearning/lib/python3.8/selectors.py", line 415, in select
    fd_event_list = self._selector.poll(timeout)
KeyboardInterrupt

During handling of the above exception, another exception occurred:

[36mray::launch_and_fit()[39m (pid=4078, ip=127.0.0.1)
ray.exceptions.TaskCancelledError: Task: TaskID(3b05f6fb74c19b99ffffffffffffffffffffffff01000000) was cancelled
[2023-10-30 18:49:56,703][flwr][ERROR] - [36mray::launch_and_fit()[39m (pid=4080, ip=127.0.0.1)
  File "/Users/tuliopolido/miniconda3/envs/FederatedLearning/lib/python3.8/site-packages/flwr/simulation/ray_transport/ray_client_proxy.py", line 148, in launch_and_fit
    return maybe_call_fit(
  File "/Users/tuliopolido/miniconda3/envs/FederatedLearning/lib/python3.8/site-packages/flwr/client/client.py", line 184, in maybe_call_fit
    return client.fit(fit_ins)
  File "/Users/tuliopolido/miniconda3/envs/FederatedLearning/lib/python3.8/site-packages/flwr/client/app.py", line 297, in _fit
    results = self.numpy_client.fit(parameters, ins.config)  # type: ignore
  File "/Users/tuliopolido/Repos/ProjetoAnaliseMobilidade/client.py", line 68, in fit
    train(self.model, self.trainloader, optim, epochs, self.device)
  File "/Users/tuliopolido/Repos/ProjetoAnaliseMobilidade/model.py", line 39, in train
    for images, labels in trainloader:
  File "/Users/tuliopolido/miniconda3/envs/FederatedLearning/lib/python3.8/site-packages/torch/utils/data/dataloader.py", line 628, in __next__
    data = self._next_data()
  File "/Users/tuliopolido/miniconda3/envs/FederatedLearning/lib/python3.8/site-packages/torch/utils/data/dataloader.py", line 1316, in _next_data
    idx, data = self._get_data()
  File "/Users/tuliopolido/miniconda3/envs/FederatedLearning/lib/python3.8/site-packages/torch/utils/data/dataloader.py", line 1282, in _get_data
    success, data = self._try_get_data()
  File "/Users/tuliopolido/miniconda3/envs/FederatedLearning/lib/python3.8/site-packages/torch/utils/data/dataloader.py", line 1120, in _try_get_data
    data = self._data_queue.get(timeout=timeout)
  File "/Users/tuliopolido/miniconda3/envs/FederatedLearning/lib/python3.8/multiprocessing/queues.py", line 107, in get
    if not self._poll(timeout):
  File "/Users/tuliopolido/miniconda3/envs/FederatedLearning/lib/python3.8/multiprocessing/connection.py", line 257, in poll
    return self._poll(timeout)
  File "/Users/tuliopolido/miniconda3/envs/FederatedLearning/lib/python3.8/multiprocessing/connection.py", line 424, in _poll
    r = wait([self], timeout)
  File "/Users/tuliopolido/miniconda3/envs/FederatedLearning/lib/python3.8/multiprocessing/connection.py", line 931, in wait
    ready = selector.select(timeout)
  File "/Users/tuliopolido/miniconda3/envs/FederatedLearning/lib/python3.8/selectors.py", line 415, in select
    fd_event_list = self._selector.poll(timeout)
KeyboardInterrupt

During handling of the above exception, another exception occurred:

[36mray::launch_and_fit()[39m (pid=4080, ip=127.0.0.1)
ray.exceptions.TaskCancelledError: Task: TaskID(c22824e0cf4c744affffffffffffffffffffffff01000000) was cancelled
[2023-10-30 18:49:56,710][flwr][ERROR] - [36mray::launch_and_fit()[39m (pid=4079, ip=127.0.0.1)
  File "/Users/tuliopolido/miniconda3/envs/FederatedLearning/lib/python3.8/site-packages/flwr/simulation/ray_transport/ray_client_proxy.py", line 148, in launch_and_fit
    return maybe_call_fit(
  File "/Users/tuliopolido/miniconda3/envs/FederatedLearning/lib/python3.8/site-packages/flwr/client/client.py", line 184, in maybe_call_fit
    return client.fit(fit_ins)
  File "/Users/tuliopolido/miniconda3/envs/FederatedLearning/lib/python3.8/site-packages/flwr/client/app.py", line 297, in _fit
    results = self.numpy_client.fit(parameters, ins.config)  # type: ignore
  File "/Users/tuliopolido/Repos/ProjetoAnaliseMobilidade/client.py", line 68, in fit
    train(self.model, self.trainloader, optim, epochs, self.device)
  File "/Users/tuliopolido/Repos/ProjetoAnaliseMobilidade/model.py", line 39, in train
    for images, labels in trainloader:
  File "/Users/tuliopolido/miniconda3/envs/FederatedLearning/lib/python3.8/site-packages/torch/utils/data/dataloader.py", line 628, in __next__
    data = self._next_data()
  File "/Users/tuliopolido/miniconda3/envs/FederatedLearning/lib/python3.8/site-packages/torch/utils/data/dataloader.py", line 1316, in _next_data
    idx, data = self._get_data()
  File "/Users/tuliopolido/miniconda3/envs/FederatedLearning/lib/python3.8/site-packages/torch/utils/data/dataloader.py", line 1282, in _get_data
    success, data = self._try_get_data()
  File "/Users/tuliopolido/miniconda3/envs/FederatedLearning/lib/python3.8/site-packages/torch/utils/data/dataloader.py", line 1120, in _try_get_data
    data = self._data_queue.get(timeout=timeout)
  File "/Users/tuliopolido/miniconda3/envs/FederatedLearning/lib/python3.8/multiprocessing/queues.py", line 107, in get
    if not self._poll(timeout):
  File "/Users/tuliopolido/miniconda3/envs/FederatedLearning/lib/python3.8/multiprocessing/connection.py", line 257, in poll
    return self._poll(timeout)
  File "/Users/tuliopolido/miniconda3/envs/FederatedLearning/lib/python3.8/multiprocessing/connection.py", line 424, in _poll
    r = wait([self], timeout)
  File "/Users/tuliopolido/miniconda3/envs/FederatedLearning/lib/python3.8/multiprocessing/connection.py", line 931, in wait
    ready = selector.select(timeout)
  File "/Users/tuliopolido/miniconda3/envs/FederatedLearning/lib/python3.8/selectors.py", line 415, in select
    fd_event_list = self._selector.poll(timeout)
KeyboardInterrupt

During handling of the above exception, another exception occurred:

[36mray::launch_and_fit()[39m (pid=4079, ip=127.0.0.1)
ray.exceptions.TaskCancelledError: Task: TaskID(349ec6f06f49652effffffffffffffffffffffff01000000) was cancelled
[2023-10-30 18:49:56,839][flwr][ERROR] - [36mray::launch_and_fit()[39m (pid=4077, ip=127.0.0.1)
  File "/Users/tuliopolido/miniconda3/envs/FederatedLearning/lib/python3.8/site-packages/flwr/simulation/ray_transport/ray_client_proxy.py", line 148, in launch_and_fit
    return maybe_call_fit(
  File "/Users/tuliopolido/miniconda3/envs/FederatedLearning/lib/python3.8/site-packages/flwr/client/client.py", line 184, in maybe_call_fit
    return client.fit(fit_ins)
  File "/Users/tuliopolido/miniconda3/envs/FederatedLearning/lib/python3.8/site-packages/flwr/client/app.py", line 297, in _fit
    results = self.numpy_client.fit(parameters, ins.config)  # type: ignore
  File "/Users/tuliopolido/Repos/ProjetoAnaliseMobilidade/client.py", line 68, in fit
    train(self.model, self.trainloader, optim, epochs, self.device)
  File "/Users/tuliopolido/Repos/ProjetoAnaliseMobilidade/model.py", line 39, in train
    for images, labels in trainloader:
  File "/Users/tuliopolido/miniconda3/envs/FederatedLearning/lib/python3.8/site-packages/torch/utils/data/dataloader.py", line 628, in __next__
    data = self._next_data()
  File "/Users/tuliopolido/miniconda3/envs/FederatedLearning/lib/python3.8/site-packages/torch/utils/data/dataloader.py", line 1316, in _next_data
    idx, data = self._get_data()
  File "/Users/tuliopolido/miniconda3/envs/FederatedLearning/lib/python3.8/site-packages/torch/utils/data/dataloader.py", line 1282, in _get_data
    success, data = self._try_get_data()
  File "/Users/tuliopolido/miniconda3/envs/FederatedLearning/lib/python3.8/site-packages/torch/utils/data/dataloader.py", line 1120, in _try_get_data
    data = self._data_queue.get(timeout=timeout)
  File "/Users/tuliopolido/miniconda3/envs/FederatedLearning/lib/python3.8/multiprocessing/queues.py", line 107, in get
    if not self._poll(timeout):
  File "/Users/tuliopolido/miniconda3/envs/FederatedLearning/lib/python3.8/multiprocessing/connection.py", line 257, in poll
    return self._poll(timeout)
  File "/Users/tuliopolido/miniconda3/envs/FederatedLearning/lib/python3.8/multiprocessing/connection.py", line 424, in _poll
    r = wait([self], timeout)
  File "/Users/tuliopolido/miniconda3/envs/FederatedLearning/lib/python3.8/multiprocessing/connection.py", line 931, in wait
    ready = selector.select(timeout)
  File "/Users/tuliopolido/miniconda3/envs/FederatedLearning/lib/python3.8/selectors.py", line 415, in select
    fd_event_list = self._selector.poll(timeout)
KeyboardInterrupt

During handling of the above exception, another exception occurred:

[36mray::launch_and_fit()[39m (pid=4077, ip=127.0.0.1)
ray.exceptions.TaskCancelledError: Task: TaskID(71dfc8e1d9348302ffffffffffffffffffffffff01000000) was cancelled
