[2023-11-16 18:26:25,974][flwr][WARNING] - 
Setting `min_available_clients` lower than `min_fit_clients` or
`min_evaluate_clients` can cause the server to fail when there are too few clients
connected to the server. `min_available_clients` must be set to a value larger
than or equal to the values of `min_fit_clients` and `min_evaluate_clients`.

[2023-11-16 18:26:25,975][flwr][INFO] - Starting Flower simulation, config: ServerConfig(num_rounds=1, round_timeout=None)
[2023-11-16 18:26:31,207][flwr][INFO] - Flower VCE: Ray initialized with resources: {'object_store_memory': 3378111283.0, 'accelerator_type:G': 1.0, 'node:192.168.100.36': 1.0, 'memory': 6756222567.0, 'CPU': 8.0, 'GPU': 1.0}
[2023-11-16 18:26:31,207][flwr][INFO] - Initializing global parameters
[2023-11-16 18:26:31,208][flwr][INFO] - Requesting initial parameters from one random client
[2023-11-16 18:26:32,265][flwr][INFO] - Received initial parameters from one random client
[2023-11-16 18:26:32,265][flwr][INFO] - Evaluating initial parameters
[2023-11-16 18:26:34,101][flwr][INFO] - initial parameters (loss, other metrics): 181.82874417304993, {'accuracy': 0.101}
[2023-11-16 18:26:34,101][flwr][INFO] - FL starting
[2023-11-16 18:26:34,102][flwr][DEBUG] - fit_round 1: strategy sampled 10 clients (out of 10)
[2023-11-16 18:27:27,707][flwr][ERROR] - [36mray::launch_and_fit()[39m (pid=21537, ip=192.168.100.36)
  File "/home/tulionpl/miniconda3/envs/FederatedLearning/lib/python3.8/site-packages/flwr/simulation/ray_transport/ray_client_proxy.py", line 148, in launch_and_fit
    return maybe_call_fit(
  File "/home/tulionpl/miniconda3/envs/FederatedLearning/lib/python3.8/site-packages/flwr/client/client.py", line 184, in maybe_call_fit
    return client.fit(fit_ins)
  File "/home/tulionpl/miniconda3/envs/FederatedLearning/lib/python3.8/site-packages/flwr/client/app.py", line 297, in _fit
    results = self.numpy_client.fit(parameters, ins.config)  # type: ignore
  File "/home/tulionpl/Repos/ProjetoAnaliseMobilidade/client.py", line 79, in fit
    calculateHash()
  File "/home/tulionpl/Repos/ProjetoAnaliseMobilidade/client.py", line 127, in calculateHash
    self.hash = random.randint(0, 256)
NameError: name 'self' is not defined
[2023-11-16 18:27:31,059][flwr][ERROR] - [36mray::launch_and_fit()[39m (pid=21540, ip=192.168.100.36)
  File "/home/tulionpl/miniconda3/envs/FederatedLearning/lib/python3.8/site-packages/flwr/simulation/ray_transport/ray_client_proxy.py", line 148, in launch_and_fit
    return maybe_call_fit(
  File "/home/tulionpl/miniconda3/envs/FederatedLearning/lib/python3.8/site-packages/flwr/client/client.py", line 184, in maybe_call_fit
    return client.fit(fit_ins)
  File "/home/tulionpl/miniconda3/envs/FederatedLearning/lib/python3.8/site-packages/flwr/client/app.py", line 297, in _fit
    results = self.numpy_client.fit(parameters, ins.config)  # type: ignore
  File "/home/tulionpl/Repos/ProjetoAnaliseMobilidade/client.py", line 79, in fit
    calculateHash()
  File "/home/tulionpl/Repos/ProjetoAnaliseMobilidade/client.py", line 127, in calculateHash
    self.hash = random.randint(0, 256)
NameError: name 'self' is not defined
[2023-11-16 18:27:31,496][flwr][ERROR] - [36mray::launch_and_fit()[39m (pid=21542, ip=192.168.100.36)
  File "/home/tulionpl/miniconda3/envs/FederatedLearning/lib/python3.8/site-packages/flwr/simulation/ray_transport/ray_client_proxy.py", line 148, in launch_and_fit
    return maybe_call_fit(
  File "/home/tulionpl/miniconda3/envs/FederatedLearning/lib/python3.8/site-packages/flwr/client/client.py", line 184, in maybe_call_fit
    return client.fit(fit_ins)
  File "/home/tulionpl/miniconda3/envs/FederatedLearning/lib/python3.8/site-packages/flwr/client/app.py", line 297, in _fit
    results = self.numpy_client.fit(parameters, ins.config)  # type: ignore
  File "/home/tulionpl/Repos/ProjetoAnaliseMobilidade/client.py", line 79, in fit
    calculateHash()
  File "/home/tulionpl/Repos/ProjetoAnaliseMobilidade/client.py", line 127, in calculateHash
    self.hash = random.randint(0, 256)
NameError: name 'self' is not defined
[2023-11-16 18:27:31,828][flwr][ERROR] - [36mray::launch_and_fit()[39m (pid=21538, ip=192.168.100.36)
  File "/home/tulionpl/miniconda3/envs/FederatedLearning/lib/python3.8/site-packages/flwr/simulation/ray_transport/ray_client_proxy.py", line 148, in launch_and_fit
    return maybe_call_fit(
  File "/home/tulionpl/miniconda3/envs/FederatedLearning/lib/python3.8/site-packages/flwr/client/client.py", line 184, in maybe_call_fit
    return client.fit(fit_ins)
  File "/home/tulionpl/miniconda3/envs/FederatedLearning/lib/python3.8/site-packages/flwr/client/app.py", line 297, in _fit
    results = self.numpy_client.fit(parameters, ins.config)  # type: ignore
  File "/home/tulionpl/Repos/ProjetoAnaliseMobilidade/client.py", line 79, in fit
    calculateHash()
  File "/home/tulionpl/Repos/ProjetoAnaliseMobilidade/client.py", line 127, in calculateHash
    self.hash = random.randint(0, 256)
NameError: name 'self' is not defined
